Workbook

Sheet Feature groups
A1: Module | B1: Feature group | C1: No. of features | D1: Explanation of the group | E1: Provided by Spotify? | F1: Spotify note | G1: Example columns | H1: Module code (GitHub)
A2: Loudness & dynamics (loudness) | B2: Overall loudness level | C2: 4 | D2: How loud the song is as a listener hears it: integrated loudness by the broadcast standard ITU-R BS.1770 (LUFS), plain RMS level, and the loudest 3-second and 0.4-second moments. | E2: Partly | F2: Spotify gives one overall loudness value (dB); the peak-moment measures are new. | G2: loudness_integrated_lufs, loudness_shortterm_max_lufs, loudness_momentary_max_lufs, ... | H2: songfeatures/features/loudness.py
A3: Loudness & dynamics (loudness) | B3: Loudness dynamics over the song | C3: 2 | D3: How much the loudness changes between quiet and loud passages (EBU Tech 3342 Loudness Range and SD of 3-s loudness). Low = flat level; high = quiet verses and big build-ups. | E3: No | G3: loudness_range_lu, loudness_shortterm_sd_lu | H3: songfeatures/features/loudness.py
A4: Loudness & dynamics (loudness) | B4: Peaks & compression (loudness war) | C4: 5 | D4: How the mastering treats peaks: sample and true peak, crest factor and peak-to-loudness ratio (low = heavily compressed/limited master) and the share of clipped samples. | E4: No | G4: true_peak_dbtp, sample_peak_dbfs, crest_factor_db, ... | H4: songfeatures/features/loudness.py
A5: Loudness & dynamics (loudness) | B5: Stereo image | C5: 3 | D5: How wide the mix is: share of side (left-right difference) energy, left-right correlation, and a mono-file flag. | E5: No | G5: stereo_width, stereo_correlation, is_mono_file | H5: songfeatures/features/loudness.py
A6: Loudness & dynamics (loudness) | B6: Duration | C6: 1 | D6: Song length in seconds. | E6: Yes | F6: Spotify duration_ms. | G6: duration_s | H6: songfeatures/features/loudness.py
A7: Timbre & spectrum (timbre) | B7: Spectral shape (brightness, noisiness) | C7: 9 | D7: Summary of the sound's spectrum: brightness (centroid, roll-off), spread, noisiness (flatness, zero-crossing rate), change over time (flux), peak-valley contrast and the overall spectral tilt. | E7: No | G7: spectral_centroid_mean_hz, spectral_centroid_sd_hz, spectral_bandwidth_mean_hz, ... | H7: songfeatures/features/timbre.py
A8: Timbre & spectrum (timbre) | B8: Frequency balance (7 bands) | C8: 7 | D8: Share of the song's energy in seven bands from sub-bass (20-60 Hz) to brilliance (6-20 kHz); e.g. bass-heavy vs bright mixes. | E8: No | G8: band_share_sub_bass, band_share_bass, band_share_low_mid, ... | H8: songfeatures/features/timbre.py
A9: Timbre & spectrum (timbre) | B9: MFCC timbre profile | C9: 26 | D9: Mean and variability of 13 mel-frequency cepstral coefficients, the standard compact description of timbre (the 'colour' of the sound) used in music and speech research. | E9: Partly | F9: Spotify's Audio Analysis endpoint gave a similar 12-number 'timbre' vector per segment (closed to new apps since Nov 2024). | G9: mfcc01_mean, mfcc01_sd, mfcc02_mean, ... | H9: songfeatures/features/timbre.py
A10: Timbre & spectrum (timbre) | B10: Timbral variability | C10: 1 | D10: How much the timbre changes from beat to beat (mean MFCC distance between consecutive beats). | E10: No | G10: timbre_change_rate | H10: songfeatures/features/timbre.py
A11: Rhythm & groove (rhythm) | B11: Tempo & tempo stability | C11: 4 | D11: Tempo in BPM plus how steady it is: local tempo variation, drift over the song and regularity of beat intervals (human vs click-track timing). | E11: Partly | F11: Spotify gives tempo only. | G11: tempo_bpm, tempo_local_cv, tempo_drift_bpm_per_min, ... | H11: songfeatures/features/rhythm.py
A12: Rhythm & groove (rhythm) | B12: Beat & pulse strength | C12: 2 | D12: How clear and strong the beat is (onset autocorrelation peak; accent on beats vs elsewhere). | E12: No | G12: pulse_clarity, beat_strength | H12: songfeatures/features/rhythm.py
A13: Rhythm & groove (rhythm) | B13: Note/drum event density | C13: 2 | D13: How many note or drum onsets occur per second and how irregular the spacing between them is. | E13: No | G13: onset_rate_per_s, ioi_entropy_bits | H13: songfeatures/features/rhythm.py
A14: Rhythm & groove (rhythm) | B14: Meter (time signature) | C14: 4 | D14: Beats per bar from neural downbeat tracking (Beat This!) with a confidence score, and a second periodicity-based 3/4-vs-4/4 estimate with its margin. | E14: Yes | F14: Spotify time_signature (3-7). | G14: beats_per_bar, beats_per_bar_confidence, time_signature_est, ... | H14: songfeatures/features/rhythm.py
A15: Rhythm & groove (rhythm) | B15: Syncopation, percussiveness & groove | C15: 4 | D15: Share of onsets on off-beats and 16th notes (syncopation), percussive vs harmonic energy, and a signal-based danceability (detrended fluctuation analysis). | E15: Partly | F15: Spotify danceability is one model score; these are interpretable signal measures. | G15: offbeat_onset_ratio, sixteenth_onset_ratio, percussive_energy_ratio, ... | H15: songfeatures/features/rhythm.py
A16: Rhythm & groove (rhythm) | B16: Method information | C16: 2 | D16: Which beat tracker was used and any error message from the optional meter model (for quality control, not analysis). | E16: No | G16: beat_tracker, meter_backend_error | H16: songfeatures/features/rhythm.py
A17: Harmony & tonality (harmony) | B17: Key & mode | C17: 6 | D17: Estimated key and major/minor mode, how clearly the music fits that key, how ambiguous it is, and a continuous major-minor score. | E17: Partly | F17: Spotify gives key and mode (confidence only in the closed Audio Analysis endpoint). | G17: key_tonic, key_mode, key_label, ... | H17: songfeatures/features/harmony.py
A18: Harmony & tonality (harmony) | B18: Modulation & tuning | C18: 4 | D18: Whether the song stays in one key, how many key changes it has, the classic late 'truck-driver' key change up, and tuning relative to A=440 Hz. | E18: No | G18: key_stability, n_key_changes, late_upward_modulation, ... | H18: songfeatures/features/harmony.py
A19: Harmony & tonality (harmony) | B19: Chords & harmonic rhythm | C19: 7 | D19: Chord sequence summary: chord changes per minute, chord length, vocabulary size and diversity, reliance on one chord, share of minor chords and of fifth-based root motion. | E19: No | G19: chord_change_rate_per_min, chord_mean_duration_beats, n_unique_chords, ... | H19: songfeatures/features/harmony.py
A20: Harmony & tonality (harmony) | B20: Harmonic colour & dissonance | C20: 4 | D20: How well the harmony fits plain triads (vs extended or ambiguous chords), how fast the tonal centre moves, and sensory roughness (dissonance). | E20: No | G20: harmonic_triadicity, harmonic_change_rate, roughness_mean, ... | H20: songfeatures/features/harmony.py
A21: Harmony & tonality (harmony) | B21: Method information | C21: 3 | D21: Which chroma, tuning and key algorithms were used (quality control). | E21: No | G21: chroma_method, tuning_method, key_method | H21: songfeatures/features/harmony.py
A22: Song structure & form (structure) | B22: Sections & repetition | C22: 6 | D22: Automatic segmentation of the song into sections: how many sections and section types, their lengths, structural complexity and how repetitive the song is. | E22: Partly | F22: Spotify's closed Audio Analysis endpoint listed section boundaries, not these summaries. | G22: n_sections, n_section_types, section_mean_duration_s, ... | H22: songfeatures/features/structure.py
A23: Song structure & form (structure) | B23: Intro & chorus (hook) | C23: 6 | D23: Length of the intro, whether the song opens with the chorus, how soon the first chorus arrives, how much of the song is chorus, how often it repeats and how much louder it is. | E23: No | G23: intro_duration_s, starts_with_chorus, time_to_first_chorus_s, ... | H23: songfeatures/features/structure.py
A24: Song structure & form (structure) | B24: Energy arc, drops & build-ups | C24: 6 | D24: The shape of loudness over time: rising or falling trend, where the climax sits, rise-then-fall arc, sudden 'drops' and gradual build-ups (common in EDM and pop). | E24: No | G24: energy_slope_lu_per_min, energy_peak_position, energy_arc_curvature, ... | H24: songfeatures/features/structure.py
A25: Song structure & form (structure) | B25: Start & ending | C25: 7 | D25: Silence at the start and end, and how the song ends: fade-out, natural decay or cold cut, with fade length. | E25: Partly | F25: Spotify's closed Audio Analysis endpoint gave fade-in end and fade-out start times. | G25: leading_silence_s, trailing_silence_s, ending_slope_lu_per_s, ... | H25: songfeatures/features/structure.py
A26: Song structure & form (structure) | B26: Method & reliability flag | C26: 2 | D26: Segmentation method used and a flag that is 0 when segmentation failed (section features are then empty). | E26: No | G26: structure_backend, structure_reliable | H26: songfeatures/features/structure.py
A27: Vocals & melody (source separation) (vocals) | B27: Instrument balance (stems) | C27: 4 | D27: After separating the song into vocals, drums, bass and other instruments (Demucs), the share of energy in each stem. | E27: No | G27: stem_share_vocals, stem_share_drums, stem_share_bass, ... | H27: songfeatures/features/vocals.py
A28: Vocals & melody (source separation) (vocals) | B28: Vocal presence & timing | C28: 5 | D28: How much of the song has vocals, whether it is instrumental, when the voice first enters, and the number and length of vocal phrases. | E28: Partly | F28: Spotify instrumentalness is one score; open_instrumentalness is built from these. | G28: vocal_presence_ratio, is_instrumental, time_to_first_vocal_s, ... | H28: songfeatures/features/vocals.py
A29: Vocals & melody (source separation) (vocals) | B29: Sung vs spoken (rap) vocals | C29: 3 | D29: How much of the vocal is sustained, pitched singing versus speech-like delivery (spoken word, rap). | E29: Partly | F29: Spotify speechiness; open_speechiness is built from these. | G29: vocal_sung_share, speech_like_seconds, speech_like_vocal_share | H29: songfeatures/features/vocals.py
A30: Vocals & melody (source separation) (vocals) | B30: Vocal pitch & range | C30: 4 | D30: Typical pitch of the lead voice (Hz and musical note number), its range and spread in semitones. | E30: No | G30: vocal_f0_median_hz, vocal_f0_median_midi, vocal_pitch_range_semitones, ... | H30: songfeatures/features/vocals.py
A31: Vocals & melody (source separation) (vocals) | B31: Intonation, pitch correction & vibrato | C31: 6 | D31: How exactly the singer hits the notes (very low values suggest Auto-Tune-style correction), how flat held notes are, and how often and how strongly vibrato is used. | E31: No | G31: pitch_grid_dev_cents, note_intonation_dev_cents, within_note_pitch_sd_cents, ... | H31: songfeatures/features/vocals.py
A32: Vocals & melody (source separation) (vocals) | B32: Melody shape | C32: 6 | D32: The vocal melody as notes: number and rate of notes, average interval size, and shares of stepwise motion, repeated notes and leaps. | E32: No | G32: n_vocal_notes, note_rate_per_vocal_s, melodic_interval_mean_abs, ... | H32: songfeatures/features/vocals.py
A33: Vocals & melody (source separation) (vocals) | B33: Method information | C33: 2 | D33: Which separation model and second voice detector were used (quality control). | E33: No | G33: separation_source, voice_gate | H33: songfeatures/features/vocals.py
A34: Voice quality (openSMILE eGeMAPS) (voice_quality) | B34: Pitch & pitch movement | C34: 10 | D34: Pitch level, variability, percentiles and rising/falling slopes of the isolated lead vocal (eGeMAPS frequency parameters). | E34: No | G34: egemaps_f0semitonefrom27_5hz_sma3nz_amean, egemaps_f0semitonefrom27_5hz_sma3nz_stddevnorm, egemaps_f0semitonefrom27_5hz_sma3nz_percentile20_0, ... | H34: songfeatures/features/voice_quality.py
A35: Voice quality (openSMILE eGeMAPS) (voice_quality) | B35: Loudness & intensity of the voice | C35: 12 | D35: How loud and dynamic the voice itself is, its loudness peaks per second and overall sound level. | E35: No | G35: egemaps_loudness_sma3_amean, egemaps_loudness_sma3_stddevnorm, egemaps_loudness_sma3_percentile20_0, ... | H35: songfeatures/features/voice_quality.py
A36: Voice quality (openSMILE eGeMAPS) (voice_quality) | B36: Voice quality (jitter, shimmer, breathiness) | C36: 10 | D36: Cycle-to-cycle pitch and amplitude irregularity (rough or creaky voice), harmonics-to-noise ratio (clear vs breathy voice) and harmonic differences linked to voice tension. | E36: No | G36: egemaps_jitterlocal_sma3nz_amean, egemaps_jitterlocal_sma3nz_stddevnorm, egemaps_shimmerlocaldb_sma3nz_amean, ... | H36: songfeatures/features/voice_quality.py
A37: Voice quality (openSMILE eGeMAPS) (voice_quality) | B37: Formants (vocal-tract resonances) | C37: 18 | D37: Frequencies, bandwidths and strengths of the first three formants, which relate to vowel quality and the singer's vocal tract. | E37: No | G37: egemaps_f1frequency_sma3nz_amean, egemaps_f1frequency_sma3nz_stddevnorm, egemaps_f1bandwidth_sma3nz_amean, ... | H37: songfeatures/features/voice_quality.py
A38: Voice quality (openSMILE eGeMAPS) (voice_quality) | B38: Spectral balance of the voice | C38: 33 | D38: Energy balance and tilt of the voice spectrum (alpha ratio, Hammarberg index, spectral slopes, flux and 4 MFCCs) for voiced and unvoiced sounds; relates to brightness, effort and timbre. | E38: No | G38: egemaps_spectralflux_sma3_amean, egemaps_spectralflux_sma3_stddevnorm, egemaps_mfcc1_sma3_amean, ... | H38: songfeatures/features/voice_quality.py
A39: Voice quality (openSMILE eGeMAPS) (voice_quality) | B39: Voiced/unvoiced timing | C39: 5 | D39: Rate and length of voiced and unvoiced stretches (articulation and phrasing tempo). | E39: No | G39: egemaps_voicedsegmentspersec, egemaps_meanvoicedsegmentlengthsec, egemaps_stddevvoicedsegmentlengthsec, ... | H39: songfeatures/features/voice_quality.py
A40: Voice quality (openSMILE eGeMAPS) (voice_quality) | B40: Amount of audio analysed | C40: 1 | D40: Seconds of vocal-active audio the measures are based on (reliability check). | E40: No | G40: voice_quality_seconds | H40: songfeatures/features/voice_quality.py
...

Sheet Modules
A1: Module | B1: No. of groups | C1: No. of features | D1: Main open-source tool | E1: Module code (GitHub)
A2: Loudness & dynamics (loudness) | B2: =COUNTIF('Feature groups'!$A$2:$A$63,A2) -> 5 | C2: =SUMIF('Feature groups'!$A$2:$A$63,A2,'Feature groups'!$C$2:$C$63) -> 15 | D2: pyloudnorm (ITU-R BS.1770-4) + own EBU Tech 3342 implementation; numpy/scipy | E2: songfeatures/features/loudness.py
A3: Timbre & spectrum (timbre) | B3: =COUNTIF('Feature groups'!$A$2:$A$63,A3) -> 4 | C3: =SUMIF('Feature groups'!$A$2:$A$63,A3,'Feature groups'!$C$2:$C$63) -> 43 | D3: librosa, scipy | E3: songfeatures/features/timbre.py
A4: Rhythm & groove (rhythm) | B4: =COUNTIF('Feature groups'!$A$2:$A$63,A4) -> 6 | C4: =SUMIF('Feature groups'!$A$2:$A$63,A4,'Feature groups'!$C$2:$C$63) -> 18 | D4: librosa (beat tracking, tempogram, onsets, HPSS); Essentia Danceability (optional) | E4: songfeatures/features/rhythm.py
A5: Harmony & tonality (harmony) | B5: =COUNTIF('Feature groups'!$A$2:$A$63,A5) -> 5 | C5: =SUMIF('Feature groups'!$A$2:$A$63,A5,'Feature groups'!$C$2:$C$63) -> 24 | D5: librosa (CQT chroma, tonnetz, Viterbi); own key/chord/roughness implementations | E5: songfeatures/features/harmony.py
A6: Song structure & form (structure) | B6: =COUNTIF('Feature groups'!$A$2:$A$63,A6) -> 5 | C6: =SUMIF('Feature groups'!$A$2:$A$63,A6,'Feature groups'!$C$2:$C$63) -> 27 | D6: librosa + scikit-learn (Laplacian segmentation); optional allin1 | E6: songfeatures/features/structure.py
A7: Vocals & melody (source separation) (vocals) | B7: =COUNTIF('Feature groups'!$A$2:$A$63,A7) -> 7 | C7: =SUMIF('Feature groups'!$A$2:$A$63,A7,'Feature groups'!$C$2:$C$63) -> 30 | D7: Demucs v4 htdemucs (source separation); librosa pYIN (f0) | E7: songfeatures/features/vocals.py
A8: Voice quality (openSMILE eGeMAPS) (voice_quality) | B8: =COUNTIF('Feature groups'!$A$2:$A$63,A8) -> 7 | C8: =SUMIF('Feature groups'!$A$2:$A$63,A8,'Feature groups'!$C$2:$C$63) -> 89 | D8: openSMILE 3 (eGeMAPSv02 functionals) on vocal-active segments of the Demucs vocal stem | E8: songfeatures/features/voice_quality.py
A9: Lyrics (Whisper transcription) (lyrics) | B9: =COUNTIF('Feature groups'!$A$2:$A$63,A9) -> 6 | C9: =SUMIF('Feature groups'!$A$2:$A$63,A9,'Feature groups'!$C$2:$C$63) -> 17 | D9: faster-whisper (Whisper large-v3 by default) on the vocal stem; VADER sentiment (English) | E9: songfeatures/features/lyrics.py
A10: Pretrained music models (Essentia / MTG) (essentia_models) | B10: =COUNTIF('Feature groups'!$A$2:$A$63,A10) -> 8 | C10: =SUMIF('Feature groups'!$A$2:$A$63,A10,'Feature groups'!$C$2:$C$63) -> 156 | D10: essentia-tensorflow with MTG pretrained models (Discogs-EffNet, MSD-MusiCNN heads) | E10: songfeatures/features/essentia_models.py
A11: Zero-shot text-audio concepts (CLAP) (clap) | B11: =COUNTIF('Feature groups'!$A$2:$A$63,A11) -> 2 | C11: =SUMIF('Feature groups'!$A$2:$A$63,A11,'Feature groups'!$C$2:$C$63) -> 32 | D11: LAION CLAP via Hugging Face transformers (default laion/larger_clap_general) | E11: songfeatures/features/clap.py
A12: Musical surprise (corpus) (surprise) | B12: =COUNTIF('Feature groups'!$A$2:$A$63,A12) -> 2 | C12: =SUMIF('Feature groups'!$A$2:$A$63,A12,'Feature groups'!$C$2:$C$63) -> 10 | D12: own interpolated n-gram model (leave-one-out over the corpus) | E12: songfeatures/corpus/surprise.py
A13: Typicality & novelty (corpus) (novelty) | B13: =COUNTIF('Feature groups'!$A$2:$A$63,A13) -> 3 | C13: =SUMIF('Feature groups'!$A$2:$A$63,A13,'Feature groups'!$C$2:$C$63) -> 21 | D13: numpy on L2-normalised song embeddings (Discogs-EffNet mean, CLAP mean) | E13: songfeatures/corpus/novelty.py
A14: Spotify-equivalent layer (open_*) (open_features) | B14: =COUNTIF('Feature groups'!$A$2:$A$63,A14) -> 2 | C14: =SUMIF('Feature groups'!$A$2:$A$63,A14,'Feature groups'!$C$2:$C$63) -> 16 | D14: Fixed formulas combining the modules above (songfeatures/derived.py) | E14: songfeatures/derived.py
A15: Total | B15: =SUM(B2:B14) -> 62 | C15: =SUM(C2:C14) -> 498

Sheet Spotify 13 features
A1: Spotify feature | B1: Pipeline column | C1: How the pipeline computes it
A2: duration_ms | B2: open_duration_ms | C2: Duration (Spotify duration_ms)
A3: tempo | B3: open_tempo | C3: Tempo (Spotify tempo) = tempo_bpm
A4: key | B4: open_key | C4: Key pitch class, 0 = C ... 11 = B, -1 if undetected (Spotify key)
A5: mode | B5: open_mode | C5: 1 = major, 0 = minor (Spotify mode)
A6: loudness | B6: open_loudness | C6: Integrated loudness (Spotify loudness is an average dB level; here ITU-R BS.1770 LUFS)
A7: time_signature | B7: open_time_signature | C7: Beats per bar on Spotify's 3-7 scale: Beat This! downbeats when the bar grid is clear (confidence >= 0.5; 2 beats per bar reported as 4), else time_signature_est (3 or 4)
A8: danceability | B8: open_danceability | C8: Danceability 0-1: Essentia danceability classifier probability; fallback DFA danceability / 3 (clipped)
A9: energy | B9: open_energy | C9: Energy 0-1: mean of 5 signal components (loudness, onset rate, >2 kHz energy share, inverse loudness range, spectral flatness; fixed ranges) averaged with model arousal when available
A10: valence | B10: open_valence | C10: Valence 0-1: (DEAM valence - 1) / 8; fallback emoMusic, then CLAP happy-vs-sad
A11: acousticness | B11: open_acousticness | C11: Acousticness 0-1: Essentia acoustic-mood probability; fallback CLAP acoustic-vs-electronic
A12: instrumentalness | B12: open_instrumentalness | C12: Instrumentalness 0-1: 1 - vocal_presence_ratio / 0.2 (clipped, from separated vocals); fallback 1 - Essentia voice probability
... A14: liveness | B14: open_liveness | C14: Liveness 0-1: CLAP P(live recording with audience vs studio)

Sheet Notes
A1: What this is | B1: Feature groups produced by the open-source audio feature pipeline (repository: github.com/pezhmanlamei/Song-Analysis). Each song gets one row in features.csv; codebook.csv describes every column.
A2: Provided by Spotify? | B2: Yes = Spotify's Web API gives an equivalent feature. Partly = Spotify gives a related single score (or gave it only in its Audio Analysis endpoint), but not the measures in this group. No = not available from Spotify.
A3: Spotify API status | B3: On 27 Nov 2024 Spotify closed its Audio Features and Audio Analysis endpoints to new apps, so the 13 features are no longer obtainable for new research projects; the open_* columns rebuild them from the full audio.
A4: Validation | B4: The pipeline was run on 100 Creative Commons songs from the Free Music Archive (10 genres) on GitHub Actions: all modules succeeded on all 100 songs.
A5: Corpus modules | B5: Musical surprise and typicality/novelty compare each song with the other songs in the dataset, so their values depend on the corpus analysed.
A6: Method rows | B6: Rows named 'Method information' or 'reliability flag' are for quality control and are not meant as analysis variables.
A7: Source | B7: Spotify for Developers blog, 'Introducing some changes to our Web API' (27 Nov 2024): https://developer.spotify.com/blog/2024-11-27-changes-to-the-web-api
